{"trial_id": "04", "hyperparameters": {"space": [{"class_name": "Choice", "config": {"name": "filters_1", "default": 16, "conditions": [], "values": [16, 32, 64], "ordered": true}}, {"class_name": "Choice", "config": {"name": "kernel_size_1", "default": 3, "conditions": [], "values": [3, 4, 5], "ordered": true}}, {"class_name": "Choice", "config": {"name": "pool_size_1", "default": 2, "conditions": [], "values": [2, 3, 4], "ordered": true}}, {"class_name": "Choice", "config": {"name": "filters_2", "default": 16, "conditions": [], "values": [16, 32, 64], "ordered": true}}, {"class_name": "Choice", "config": {"name": "kernel_size_2", "default": 3, "conditions": [], "values": [3, 4, 5], "ordered": true}}, {"class_name": "Choice", "config": {"name": "pool_size_2", "default": 2, "conditions": [], "values": [2, 3, 4], "ordered": true}}, {"class_name": "Choice", "config": {"name": "filters_3", "default": 16, "conditions": [], "values": [16, 32, 64], "ordered": true}}, {"class_name": "Choice", "config": {"name": "kernel_size_3", "default": 3, "conditions": [], "values": [3, 4, 5], "ordered": true}}, {"class_name": "Choice", "config": {"name": "pool_size_3", "default": 2, "conditions": [], "values": [2, 3, 4], "ordered": true}}, {"class_name": "Choice", "config": {"name": "units", "default": 32, "conditions": [], "values": [32, 64, 96], "ordered": true}}], "values": {"filters_1": 64, "kernel_size_1": 5, "pool_size_1": 3, "filters_2": 64, "kernel_size_2": 3, "pool_size_2": 4, "filters_3": 32, "kernel_size_3": 4, "pool_size_3": 2, "units": 64}}, "metrics": {"metrics": {}}, "score": null, "best_step": 0, "status": "FAILED", "message": "Traceback (most recent call last):\n  File \"c:\\Users\\lucia\\anaconda3\\lib\\site-packages\\keras_tuner\\src\\engine\\base_tuner.py\", line 274, in _try_run_and_update_trial\n    self._run_and_update_trial(trial, *fit_args, **fit_kwargs)\n  File \"c:\\Users\\lucia\\anaconda3\\lib\\site-packages\\keras_tuner\\src\\engine\\base_tuner.py\", line 239, in _run_and_update_trial\n    results = self.run_trial(trial, *fit_args, **fit_kwargs)\n  File \"c:\\Users\\lucia\\anaconda3\\lib\\site-packages\\keras_tuner\\src\\engine\\tuner.py\", line 314, in run_trial\n    obj_value = self._build_and_fit_model(trial, *args, **copied_kwargs)\n  File \"c:\\Users\\lucia\\anaconda3\\lib\\site-packages\\keras_tuner\\src\\engine\\tuner.py\", line 232, in _build_and_fit_model\n    model = self._try_build(hp)\n  File \"c:\\Users\\lucia\\anaconda3\\lib\\site-packages\\keras_tuner\\src\\engine\\tuner.py\", line 164, in _try_build\n    model = self._build_hypermodel(hp)\n  File \"c:\\Users\\lucia\\anaconda3\\lib\\site-packages\\keras_tuner\\src\\engine\\tuner.py\", line 155, in _build_hypermodel\n    model = self.hypermodel.build(hp)\n  File \"C:\\Users\\lucia\\AppData\\Local\\Temp\\ipykernel_14428\\1877652515.py\", line 6, in build\n    model = keras.Sequential([\n  File \"c:\\Users\\lucia\\anaconda3\\lib\\site-packages\\tensorflow\\python\\trackable\\base.py\", line 204, in _method_wrapper\n    result = method(self, *args, **kwargs)\n  File \"c:\\Users\\lucia\\anaconda3\\lib\\site-packages\\keras\\src\\utils\\traceback_utils.py\", line 70, in error_handler\n    raise e.with_traceback(filtered_tb) from None\n  File \"c:\\Users\\lucia\\anaconda3\\lib\\site-packages\\tensorflow\\python\\framework\\ops.py\", line 1020, in _create_c_op\n    raise ValueError(e.message)\nValueError: Exception encountered when calling layer \"maxPooling_3\" (type MaxPooling2D).\n\nNegative dimension size caused by subtracting 2 from 1 for '{{node maxPooling_3/MaxPool}} = MaxPool[T=DT_FLOAT, data_format=\"NHWC\", explicit_paddings=[], ksize=[1, 2, 2, 1], padding=\"VALID\", strides=[1, 2, 2, 1]](Placeholder)' with input shapes: [?,1,1,32].\n\nCall arguments received by layer \"maxPooling_3\" (type MaxPooling2D):\n  \u2022 inputs=tf.Tensor(shape=(None, 1, 1, 32), dtype=float32)\n"}