{"trial_id": "14", "hyperparameters": {"space": [{"class_name": "Choice", "config": {"name": "filters_1", "default": 16, "conditions": [], "values": [16, 32, 64], "ordered": true}}, {"class_name": "Choice", "config": {"name": "kernel_size_1", "default": 3, "conditions": [], "values": [3, 4, 5], "ordered": true}}, {"class_name": "Choice", "config": {"name": "pool_size_1", "default": 2, "conditions": [], "values": [2, 3, 4], "ordered": true}}, {"class_name": "Choice", "config": {"name": "filters_2", "default": 16, "conditions": [], "values": [16, 32, 64], "ordered": true}}, {"class_name": "Choice", "config": {"name": "kernel_size_2", "default": 3, "conditions": [], "values": [3, 4, 5], "ordered": true}}, {"class_name": "Choice", "config": {"name": "pool_size_2", "default": 2, "conditions": [], "values": [2, 3, 4], "ordered": true}}, {"class_name": "Choice", "config": {"name": "filters_3", "default": 16, "conditions": [], "values": [16, 32, 64], "ordered": true}}, {"class_name": "Choice", "config": {"name": "kernel_size_3", "default": 3, "conditions": [], "values": [3, 4, 5], "ordered": true}}, {"class_name": "Choice", "config": {"name": "pool_size_3", "default": 2, "conditions": [], "values": [2, 3, 4], "ordered": true}}, {"class_name": "Choice", "config": {"name": "units", "default": 32, "conditions": [], "values": [32, 64, 96], "ordered": true}}], "values": {"filters_1": 32, "kernel_size_1": 3, "pool_size_1": 4, "filters_2": 16, "kernel_size_2": 4, "pool_size_2": 4, "filters_3": 16, "kernel_size_3": 5, "pool_size_3": 2, "units": 96}}, "metrics": {"metrics": {}}, "score": null, "best_step": 0, "status": "FAILED", "message": "Traceback (most recent call last):\n  File \"c:\\Users\\lucia\\anaconda3\\lib\\site-packages\\keras_tuner\\src\\engine\\base_tuner.py\", line 274, in _try_run_and_update_trial\n    self._run_and_update_trial(trial, *fit_args, **fit_kwargs)\n  File \"c:\\Users\\lucia\\anaconda3\\lib\\site-packages\\keras_tuner\\src\\engine\\base_tuner.py\", line 239, in _run_and_update_trial\n    results = self.run_trial(trial, *fit_args, **fit_kwargs)\n  File \"c:\\Users\\lucia\\anaconda3\\lib\\site-packages\\keras_tuner\\src\\engine\\tuner.py\", line 314, in run_trial\n    obj_value = self._build_and_fit_model(trial, *args, **copied_kwargs)\n  File \"c:\\Users\\lucia\\anaconda3\\lib\\site-packages\\keras_tuner\\src\\engine\\tuner.py\", line 232, in _build_and_fit_model\n    model = self._try_build(hp)\n  File \"c:\\Users\\lucia\\anaconda3\\lib\\site-packages\\keras_tuner\\src\\engine\\tuner.py\", line 164, in _try_build\n    model = self._build_hypermodel(hp)\n  File \"c:\\Users\\lucia\\anaconda3\\lib\\site-packages\\keras_tuner\\src\\engine\\tuner.py\", line 155, in _build_hypermodel\n    model = self.hypermodel.build(hp)\n  File \"C:\\Users\\lucia\\AppData\\Local\\Temp\\ipykernel_1712\\3897756079.py\", line 6, in build\n    model = keras.Sequential([\n  File \"c:\\Users\\lucia\\anaconda3\\lib\\site-packages\\tensorflow\\python\\trackable\\base.py\", line 204, in _method_wrapper\n    result = method(self, *args, **kwargs)\n  File \"c:\\Users\\lucia\\anaconda3\\lib\\site-packages\\keras\\src\\utils\\traceback_utils.py\", line 70, in error_handler\n    raise e.with_traceback(filtered_tb) from None\n  File \"c:\\Users\\lucia\\anaconda3\\lib\\site-packages\\keras\\src\\layers\\convolutional\\base_conv.py\", line 354, in compute_output_shape\n    raise ValueError(\nValueError: One of the dimensions in the output is <= 0 due to downsampling in convolutional_3. Consider increasing the input size. Received input shape [None, 3, 3, 16] which would produce output shape with a zero or negative value in a dimension.\n"}